<mujoco model="rhand_mano">
    <compiler angle="radian" meshdir="./meshes/" />
    <size njmax="500" nconmax="100" />
    <default>
        <!-- 关节默认参数分类 -->
        <!-- <joint dclass="wrist" stiffness="250" damping="45"/> -->
        <joint dclass="wrist" stiffness="1500" damping="50"/>
        <joint dclass="mcp" stiffness="180" damping="35"/>
        <joint dclass="pip" stiffness="120" damping="25"/>
        <joint dclass="dip" stiffness="80" damping="18"/>
        <!-- 执行器默认配置 -->
        <motor dclass="wrist" gear="200"/>
        <motor dclass="mcp" gear="100"/>
        <motor dclass="pip" gear="80"/>
        <motor dclass="dip" gear="50"/>
    </default>

    <asset>
        <mesh name="right_wrist" file="right_wrist.stl" />
        <mesh name="right_index1" file="right_index1.stl" />
        <mesh name="right_index2" file="right_index2.stl" />
        <mesh name="right_index3" file="right_index3.stl" />
        <mesh name="right_middle1" file="right_middle1.stl" />
        <mesh name="right_middle2" file="right_middle2.stl" />
        <mesh name="right_middle3" file="right_middle3.stl" />
        <mesh name="right_pinky1" file="right_pinky1.stl" />
        <mesh name="right_pinky2" file="right_pinky2.stl" />
        <mesh name="right_pinky3" file="right_pinky3.stl" />
        <mesh name="right_ring1" file="right_ring1.stl" />
        <mesh name="right_ring2" file="right_ring2.stl" />
        <mesh name="right_ring3" file="right_ring3.stl" />
        <mesh name="right_thumb1" file="right_thumb1.stl" />
        <mesh name="right_thumb2" file="right_thumb2.stl" />
        <mesh name="right_thumb3" file="right_thumb3.stl" />
    </asset>
    <worldbody>
        <body name="root" pos="0 0 0">
            <body name="right_wrist_x" pos="0 0 0">
                <inertial pos="-0.0342879 -0.00198336 4.85957e-05" quat="1 6.91213e-05 0.000112204 0.000149355" mass="0.01" diaginertia="0.01 0.01 0.01" />
                <joint name="right_wrist_x" pos="0 0 0" axis="1 0 0" type="slide" limited="true" range="-2 2" dclass="wrist" frictionloss="0.0001" />
                <body name="right_wrist_y" pos="0 0 0">
                    <inertial pos="0 0 0" mass="0.01" diaginertia="0.01 0.01 0.01" />
                    <joint name="right_wrist_y" pos="0 0 0" axis="0 1 0" type="slide" limited="true" range="-2 2" dclass="wrist" frictionloss="0.0001" />
                    <body name="right_wrist_z" pos="0 0 0">
                        <inertial pos="0 0 0" mass="0.01" diaginertia="0.01 0.01 0.01" />
                        <joint name="right_wrist_z" pos="0 0 0" axis="0 0 1" type="slide" limited="true" range="-2 2" dclass="wrist" frictionloss="0.0001" />
                        <body name="right_wrist_rx" pos="0 0 0">
                            <inertial pos="0 0 0" mass="0.01" diaginertia="0.01 0.01 0.01" />
                            <joint name="right_wrist_rx" pos="0 0 0" axis="1 0 0" limited="true" range="-6.28 6.28" dclass="wrist" frictionloss="0.0001" />
                            <body name="right_wrist_ry" pos="0 0 0">
                                <inertial pos="0 0 0" mass="0.01" diaginertia="0.01 0.01 0.01" />
                                <joint name="right_wrist_ry" pos="0 0 0" axis="0 1 0" limited="true" range="-6.28 6.28" dclass="wrist" frictionloss="0.0001" />
                                <body name="right_wrist" pos="0 0 0">
                                    <inertial pos="0 0 0" mass="0.06" diaginertia="0.06 0.06 0.06" />
                                    <joint name="right_wrist" pos="0 0 0" axis="0 0 1" limited="true" range="-6.28 6.28" dclass="wrist" frictionloss="0.0001" />
                                    <geom pos="-0.0956699 -0.00638343 -0.0061863" type="mesh" contype="0" conaffinity="0" group="1" rgba="0.917969 0.765 0.5234 1" mesh="right_wrist" />
                                    <geom size="0.0439 0.0135 0.035" pos="-0.0392211 -0.00378517 -0.000630835" quat="0.996311 0.00681974 -0.0706646 0.0482078" type="box" rgba="0.917969 0.765 0.5234 1" />
                                    <geom size="0.015 0.0117845" pos="-0.0144538 -0.0093134 0.0154877" quat="0.913582 0.220263 -0.341835 0" type="capsule" rgba="0.917969 0.765 0.5234 1" />
                                    <body name="right_index1" pos="-0.0880973 -0.00520036 0.020686">
                                        <inertial pos="-0.0184105 0.00337297 0.00148585" quat="0.00227126 0.676555 -0.0419441 0.735193" mass="0.00885801" diaginertia="8.33438e-07 8.00909e-07 4.40063e-07" />
                                        <joint name="right_index1_x" pos="0 0 0" axis="1 0 0" limited="true" range="-0.14 0.46" dclass="mcp" frictionloss="0.0001" />
                                        <body name="right_index1_y" pos="0 0 0">
                                            <inertial pos="0 0 0" mass="0.01" diaginertia="0.01 0.01 0.01" />
                                            <joint name="right_index1_y" pos="0 0 0" axis="0 1 0" limited="true" range="-0.61 0.32" dclass="mcp" frictionloss="0.0001" />
                                            <body name="right_index1_z" pos="0 0 0">
                                                <inertial pos="0 0 0" mass="0.01" diaginertia="0.01 0.01 0.01" />
                                                <joint name="right_index1_z" pos="0 0 0" axis="0 0 1" limited="true" range="-0.38 1.25" dclass="mcp" frictionloss="0.0001" />
                                                <geom pos="-0.00757268 -0.00118307 -0.0268723" type="mesh" contype="0" conaffinity="0" group="1" rgba="0.917969 0.765 0.5234 1" mesh="right_index1" />
                                                <geom size="0.009 0.0119992" pos="-0.011883 0.00145792 0.000806192" quat="0.730475 -0.0831659 -0.677857 0" type="capsule" rgba="0.917969 0.765 0.5234 1" />
                                                <body name="right_index2" pos="-0.0326789 0.00400936 0.00221707">
                                                    <inertial pos="-0.0112131 -0.000167142 2.32336e-05" quat="0.436117 0.481284 0.415986 0.636493" mass="0.00429965" diaginertia="2.26068e-07 2.05281e-07 1.5109e-07" />
                                                    <joint name="right_index2_x" pos="0 0 0" axis="1 0 0" limited="true" range="-0.43 0.58" dclass="pip" frictionloss="0.0001" />
                                                    <body name="right_index2_y" pos="0 0 0">
                                                        <inertial pos="0 0 0" mass="0.01" diaginertia="0.01 0.01 0.01" />
                                                        <joint name="right_index2_y" pos="0 0 0" axis="0 1 0" limited="true" range="-0.26 0.21" dclass="pip" frictionloss="0.0001" />
                                                        <body name="right_index2_z" pos="0 0 0">
                                                            <inertial pos="0 0 0" mass="0.01" diaginertia="0.01 0.01 0.01" />
                                                            <joint name="right_index2_z" pos="0 0 0" axis="0 0 1" limited="true" range="-0.14 1.3" dclass="pip" frictionloss="0.0001" />
                                                            <geom pos="0.0251062 -0.00519243 -0.0290894" type="mesh" contype="0" conaffinity="0" group="1" rgba="0.917969 0.765 0.5234 1" mesh="right_index2" />
                                                            <geom size="0.0075 0.00734711" pos="-0.00733443 -0.000429826 -3.77775e-05" quat="0.705287 0.0414745 -0.707708 0" type="capsule" rgba="0.917969 0.765 0.5234 1" />
                                                            <body name="right_index3" pos="-0.0221559 -0.00129842 -0.000114119">
                                                                <inertial pos="-0.0111328 -0.000501862 -0.000143096" quat="0.598112 0.404056 0.535204 0.438814" mass="0.00309571" diaginertia="1.58586e-07 1.42543e-07 7.39047e-08" />
                                                                <joint name="right_index3_x" pos="0 0 0" axis="1 0 0" limited="true" range="-0.39 0.43" dclass="dip" frictionloss="0.0001" />
                                                                <body name="right_index3_y" pos="0 0 0">
                                                                    <inertial pos="0 0 0" mass="0.01" diaginertia="0.01 0.01 0.01" />
                                                                    <joint name="right_index3_y" pos="0 0 0" axis="0 1 0" limited="true" range="-0.17 0.35" dclass="dip" frictionloss="0.0001" />
                                                                    <body name="right_index3_z" pos="0 0 0">
                                                                        <inertial pos="-0.0127411 0.000592058 -0.000250692" quat="0.0165763 0.699936 -0.0162537 0.713828" mass="0.02" diaginertia="0.0200033 0.0200033 0.02" />
                                                                        <joint name="right_index3_z" pos="0 0 0" axis="0 0 1" limited="true" range="-0.25 1.15" dclass="dip" frictionloss="0.0001" />
                                                                        <geom pos="0.0472621 -0.003894 -0.0289752" type="mesh" contype="0" conaffinity="0" group="1" rgba="0.917969 0.765 0.5234 1" mesh="right_index3" />
                                                                        <geom size="0.0075 0.00902586" pos="-0.00900129 -0.000641441 -0.000177108" quat="0.700135 0.0507524 -0.712205 0" type="capsule" rgba="0.917969 0.765 0.5234 1" />
                                                                    </body>
                                                                </body>
                                                            </body>
                                                        </body>
                                                    </body>
                                                </body>
                                            </body>
                                        </body>
                                    </body>
                                    <body name="right_middle1" pos="-0.0946605 -0.00147896 -0.00335754">
                                        <inertial pos="-0.0140409 0.00236965 -0.00297553" quat="0.61092 0.387719 0.482166 0.49393" mass="0.0104123" diaginertia="1.20313e-06 1.15795e-06 5.34769e-07" />
                                        <joint name="right_middle1_x" pos="0 0 0" axis="1 0 0" limited="true" range="-0.5 0.42" dclass="mcp" frictionloss="0.0001" />
                                        <body name="right_middle1_y" pos="0 0 0">
                                            <inertial pos="0 0 0" mass="0.01" diaginertia="0.01 0.01 0.01" />
                                            <joint name="right_middle1_y" pos="0 0 0" axis="0 1 0" limited="true" range="-0.61 0.21" dclass="mcp" frictionloss="0.0001" />
                                            <body name="right_middle1_z" pos="0 0 0">
                                                <inertial pos="0 0 0" mass="0.01" diaginertia="0.01 0.01 0.01" />
                                                <joint name="right_middle1_z" pos="0 0 0" axis="0 0 1" limited="true" range="-0.49 1.44" dclass="mcp" frictionloss="0.0001" />
                                                <geom pos="-0.00100949 -0.00490447 -0.00282876" type="mesh" contype="0" conaffinity="0" group="1" rgba="0.917969 0.765 0.5234 1" mesh="right_middle1" />
                                                <geom size="0.009 0.0113676" pos="-0.0111697 0.000666731 -0.00200396" quat="0.64176 -0.0456961 -0.765543 0" type="capsule" rgba="0.917969 0.765 0.5234 1" />
                                                <body name="right_middle2" pos="-0.0311827 0.00186133 -0.00559451">
                                                    <inertial pos="-0.0130836 -0.000209653 -0.00221531" quat="0.52861 0.334981 0.537432 0.565267" mass="0.00413492" diaginertia="2.07183e-07 1.92604e-07 1.43804e-07" />
                                                    <joint name="right_middle2_x" pos="0 0 0" axis="1 0 0" limited="true" range="-0.47 0.02" dclass="pip" frictionloss="0.0001" />
                                                    <body name="right_middle2_y" pos="0 0 0">
                                                        <inertial pos="0 0 0" mass="0.01" diaginertia="0.01 0.01 0.01" />
                                                        <joint name="right_middle2_y" pos="0 0 0" axis="0 1 0" limited="true" range="-0.29 0.05" dclass="pip" frictionloss="0.0001" />
                                                        <body name="right_middle2_z" pos="0 0 0">
                                                            <inertial pos="0 0 0" mass="0.01" diaginertia="0.01 0.01 0.01" />
                                                            <joint name="right_middle2_z" pos="0 0 0" axis="0 0 1" limited="true" range="-0.45 1.33" dclass="pip" frictionloss="0.0001" />
                                                            <geom pos="0.0301732 -0.00676579 0.00276574" type="mesh" contype="0" conaffinity="0" group="1" rgba="0.917969 0.765 0.5234 1" mesh="right_middle2" />
                                                            <geom size="0.0075 0.00788775" pos="-0.00776207 -0.000424321 -0.00133674" quat="0.64441 0.0417397 -0.76354 0" type="capsule" rgba="0.917969 0.765 0.5234 1" />
                                                            <body name="right_middle3" pos="-0.0229046 -0.0012521 -0.00394451">
                                                                <inertial pos="-0.013412 -0.00013217 -0.00208169" quat="0.651508 0.408066 0.461417 0.442847" mass="0.00301659" diaginertia="1.38969e-07 1.27402e-07 7.54781e-08" />
                                                                <joint name="right_middle3_x" pos="0 0 0" axis="1 0 0" limited="true" range="-0.38 0" dclass="dip" frictionloss="0.0001" />
                                                                <body name="right_middle3_y" pos="0 0 0">
                                                                    <inertial pos="0 0 0" mass="0.01" diaginertia="0.01 0.01 0.01" />
                                                                    <joint name="right_middle3_y" pos="0 0 0" axis="0 1 0" limited="true" range="-0.14 0.22" dclass="dip" frictionloss="0.0001" />
                                                                    <body name="right_middle3_z" pos="0 0 0">
                                                                        <inertial pos="-0.0128461 0.00192343 -0.00206812" quat="0.0475435 0.646735 -0.0558099 0.759183" mass="0.02" diaginertia="0.0200035 0.0200035 0.02" />
                                                                        <joint name="right_middle3_z" pos="0 0 0" axis="0 0 1" limited="true" range="-0.35 0.88" dclass="dip" frictionloss="0.0001" />
                                                                        <geom pos="0.0530778 -0.00551369 0.00671026" type="mesh" contype="0" conaffinity="0" group="1" rgba="0.917969 0.765 0.5234 1" mesh="right_middle3" />
                                                                        <geom size="0.0075 0.00926838" pos="-0.00914571 0.000301456 -0.00147239" quat="0.648513 -0.0250767 -0.76079 0" type="capsule" rgba="0.917969 0.765 0.5234 1" />
                                                                    </body>
                                                                </body>
                                                            </body>
                                                        </body>
                                                    </body>
                                                </body>
                                            </body>
                                        </body>
                                    </body>
                                    <body name="right_pinky1" pos="-0.068787 -0.00994033 -0.0432093">
                                        <inertial pos="-0.00729834 0.00120967 -0.00707704" quat="0.646146 0.313768 0.357742 0.596712" mass="0.00429689" diaginertia="2.24589e-07 2.13335e-07 1.48827e-07" />
                                        <joint name="right_pinky1_x" pos="0 0 0" axis="1 0 0" limited="true" range="-1.31 0.42" dclass="mcp" frictionloss="0.0001" />
                                        <body name="right_pinky1_y" pos="0 0 0">
                                            <inertial pos="0 0 0" mass="0.01" diaginertia="0.01 0.01 0.01" />
                                            <joint name="right_pinky1_y" pos="0 0 0" axis="0 1 0" limited="true" range="-0.63 0.62" dclass="mcp" frictionloss="0.0001" />
                                            <body name="right_pinky1_z" pos="0 0 0">
                                                <inertial pos="0 0 0" mass="0.01" diaginertia="0.01 0.01 0.01" />
                                                <joint name="right_pinky1_z" pos="0 0 0" axis="0 0 1" limited="true" range="-0.06 1.65" dclass="mcp" frictionloss="0.0001" />
                                                <geom pos="-0.026883 0.0035569 0.037023" type="mesh" contype="0" conaffinity="0" group="1" rgba="0.917969 0.765 0.5234 1" mesh="right_pinky1" />
                                                <geom size="0.009 0.00605596" pos="-0.00488059 1.77346e-05 -0.00358528" quat="0.45165 -0.00324194 -0.892189 0" type="capsule" rgba="0.917969 0.765 0.5234 1" />
                                                <body name="right_pinky2" pos="-0.0170144 6.18252e-05 -0.0124988">
                                                    <inertial pos="-0.00786047 0.00108253 -0.00618461" quat="0.739218 0.206766 0.43978 0.46626" mass="0.00278161" diaginertia="1.10336e-07 1.03788e-07 7.1461e-08" />
                                                    <joint name="right_pinky2_x" pos="0 0 0" axis="1 0 0" limited="true" range="-1.11 0.98" dclass="pip" frictionloss="0.0001" />
                                                    <body name="right_pinky2_y" pos="0 0 0">
                                                        <inertial pos="0 0 0" mass="0.01" diaginertia="0.01 0.01 0.01" />
                                                        <joint name="right_pinky2_y" pos="0 0 0" axis="0 1 0" limited="true" range="-0.42 0.61" dclass="pip" frictionloss="0.0001" />
                                                        <body name="right_pinky2_z" pos="0 0 0">
                                                            <inertial pos="0 0 0" mass="0.01" diaginertia="0.01 0.01 0.01" />
                                                            <joint name="right_pinky2_z" pos="0 0 0" axis="0 0 1" limited="true" range="-0.37 1.29" dclass="pip" frictionloss="0.0001" />
                                                            <geom pos="-0.00986855 0.00349507 0.0495218" type="mesh" contype="0" conaffinity="0" group="1" rgba="0.917969 0.765 0.5234 1" mesh="right_pinky2" />
                                                            <geom size="0.0075 0.00572344" pos="-0.00479305 -0.000208783 -0.00312104" quat="0.476808 0.038253 -0.878175 0" type="capsule" rgba="0.917969 0.765 0.5234 1" />
                                                            <body name="right_pinky3" pos="-0.0158669 -0.000691156 -0.0103319">
                                                                <inertial pos="-0.00881048 -0.000957834 -0.00502779" quat="0.645954 0.332379 0.389167 0.566408" mass="0.00156606" diaginertia="4.44371e-08 4.12099e-08 2.61844e-08" />
                                                                <joint name="right_pinky3_x" pos="0 0 0" axis="1 0 0" limited="true" range="-1.16 0.46" dclass="dip" frictionloss="0.0001" />
                                                                <body name="right_pinky3_y" pos="0 0 0">
                                                                    <inertial pos="0 0 0" mass="0.01" diaginertia="0.01 0.01 0.01" />
                                                                    <joint name="right_pinky3_y" pos="0 0 0" axis="0 1 0" limited="true" range="-0.25 0.51" dclass="dip" frictionloss="0.0001" />
                                                                    <body name="right_pinky3_z" pos="0 0 0">
                                                                        <inertial pos="-0.00854671 0.000774338 -0.00515769" quat="0.0190236 0.491222 -0.0336993 0.870175" mass="0.02" diaginertia="0.020002 0.020002 0.02" />
                                                                        <joint name="right_pinky3_z" pos="0 0 0" axis="0 0 1" limited="true" range="-1.06 0.46" dclass="dip" frictionloss="0.0001" />
                                                                        <geom pos="0.00599835 0.00418623 0.0598537" type="mesh" contype="0" conaffinity="0" group="1" rgba="0.917969 0.765 0.5234 1" mesh="right_pinky3" />
                                                                        <geom size="0.0065 0.00675873" pos="-0.00577145 -0.000490027 -0.0034829" quat="0.492281 0.0736398 -0.867316 0" type="capsule" rgba="0.917969 0.765 0.5234 1" />
                                                                    </body>
                                                                </body>
                                                            </body>
                                                        </body>
                                                    </body>
                                                </body>
                                            </body>
                                        </body>
                                    </body>
                                    <body name="right_ring1" pos="-0.0817356 -0.00395742 -0.0266732">
                                        <inertial pos="-0.0122936 0.00247827 -0.000698965" quat="-0.202439 0.608815 -0.140617 0.754049" mass="0.00756622" diaginertia="5.9483e-07 5.75582e-07 3.61418e-07" />
                                        <joint name="right_ring1_x" pos="0 0 0" axis="1 0 0" limited="true" range="-0.45 0.32" dclass="mcp" frictionloss="0.0001" />
                                        <body name="right_ring1_y" pos="0 0 0">
                                            <inertial pos="0 0 0" mass="0.01" diaginertia="0.01 0.01 0.01" />
                                            <joint name="right_ring1_y" pos="0 0 0" axis="0 1 0" limited="true" range="-0.44 0.35" dclass="mcp" frictionloss="0.0001" />
                                            <body name="right_ring1_z" pos="0 0 0">
                                                <inertial pos="0 0 0" mass="0.01" diaginertia="0.01 0.01 0.01" />
                                                <joint name="right_ring1_z" pos="0 0 0" axis="0 0 1" limited="true" range="-0.28 1.48" dclass="mcp" frictionloss="0.0001" />
                                                <geom pos="-0.0139344 -0.00242601 0.0204869" type="mesh" contype="0" conaffinity="0" group="1" rgba="0.917969 0.765 0.5234 1" mesh="right_ring1" />
                                                <geom size="0.009 0.00992191" pos="-0.00973975 0.000711024 -0.00175383" quat="0.641575 -0.0558486 -0.765025 0" type="capsule" rgba="0.917969 0.765 0.5234 1" />
                                                <body name="right_ring2" pos="-0.0283143 0.00206701 -0.00509854">
                                                    <inertial pos="-0.0112011 -0.00038999 -0.00420265" quat="0.609508 0.343103 0.489345 0.520886" mass="0.00502999" diaginertia="3.48968e-07 3.41699e-07 1.62903e-07" />
                                                    <joint name="right_ring2_x" pos="0 0 0" axis="1 0 0" limited="true" range="-0.58 -0.11" dclass="pip" frictionloss="0.0001" />
                                                    <body name="right_ring2_y" pos="0 0 0">
                                                        <inertial pos="0 0 0" mass="0.01" diaginertia="0.01 0.01 0.01" />
                                                        <joint name="right_ring2_y" pos="0 0 0" axis="0 1 0" limited="true" range="-0.47 0.3" dclass="pip" frictionloss="0.0001" />
                                                        <body name="right_ring2_z" pos="0 0 0">
                                                            <inertial pos="0 0 0" mass="0.01" diaginertia="0.01 0.01 0.01" />
                                                            <joint name="right_ring2_z" pos="0 0 0" axis="0 0 1" limited="true" range="-0.35 1.46" dclass="pip" frictionloss="0.0001" />
                                                            <geom pos="0.0143799 -0.00449301 0.0255854" type="mesh" contype="0" conaffinity="0" group="1" rgba="0.917969 0.765 0.5234 1" mesh="right_ring2" />
                                                            <geom size="0.0075 0.00864294" pos="-0.0082017 -0.000588652 -0.00266194" quat="0.588222 0.057893 -0.806625 0" type="capsule" rgba="0.917969 0.765 0.5234 1" />
                                                            <body name="right_ring3" pos="-0.0235205 -0.00168811 -0.00763382">
                                                                <inertial pos="-0.0119942 -8.53267e-05 -0.00351911" quat="0.646087 0.373119 0.460429 0.480998" mass="0.00288135" diaginertia="1.39954e-07 1.31092e-07 6.33951e-08" />
                                                                <joint name="right_ring3_x" pos="0 0 0" axis="1 0 0" limited="true" range="-0.45 -0.01" dclass="dip" frictionloss="0.0001" />
                                                                <body name="right_ring3_y" pos="0 0 0">
                                                                    <inertial pos="0 0 0" mass="0.01" diaginertia="0.01 0.01 0.01" />
                                                                    <joint name="right_ring3_y" pos="0 0 0" axis="0 1 0" limited="true" range="-0.08 0.33" dclass="dip" frictionloss="0.0001" />
                                                                    <body name="right_ring3_z" pos="0 0 0">
                                                                        <inertial pos="-0.0122178 0.00192946 -0.00367024" quat="0.597429 0.463346 0.378257 0.534145" mass="0.02" diaginertia="0.0200033 0.0200033 0.02" />
                                                                        <joint name="right_ring3_z" pos="0 0 0" axis="0 0 1" limited="true" range="-0.28 0.77" dclass="dip" frictionloss="0.0001" />
                                                                        <geom pos="0.0379004 -0.0028049 0.0332192" type="mesh" contype="0" conaffinity="0" group="1" rgba="0.917969 0.765 0.5234 1" mesh="right_ring3" />
                                                                        <geom size="0.0075 0.00901444" pos="-0.00862842 0.000303293 -0.00259198" quat="0.596852 -0.0281856 -0.801856 0" type="capsule" rgba="0.917969 0.765 0.5234 1" />
                                                                    </body>
                                                                </body>
                                                            </body>
                                                        </body>
                                                    </body>
                                                </body>
                                            </body>
                                        </body>
                                    </body>
                                    <body name="right_thumb1" pos="-0.0240897 -0.0155223 0.0258128">
                                        <inertial pos="-0.00536514 -0.00257659 0.0129758" quat="-0.285015 0.727535 -0.229445 0.580357" mass="0.013891" diaginertia="2.22911e-06 1.48365e-06 1.23544e-06" />
                                        <joint name="right_thumb1_x" pos="0 0 0" axis="1 0 0" limited="true" range="-1.9 2.43" dclass="mcp" frictionloss="0.0001" />
                                        <body name="right_thumb1_y" pos="0 0 0">
                                            <inertial pos="0 0 0" mass="0.01" diaginertia="0.01 0.01 0.01" />
                                            <joint name="right_thumb1_y" pos="0 0 0" axis="0 1 0" limited="true" range="-1.96 2.03" dclass="mcp" frictionloss="0.0001" />
                                            <body name="right_thumb1_z" pos="0 0 0">
                                                <inertial pos="0 0 0" mass="0.01" diaginertia="0.01 0.01 0.01" />
                                                <joint name="right_thumb1_z" pos="0 0 0" axis="0 0 1" limited="true" range="-1.94 2.6" dclass="mcp" frictionloss="0.0001" />
                                                <geom pos="-0.0715802 0.00913891 -0.0319991" type="mesh" contype="0" conaffinity="0" group="1" rgba="0.917969 0.765 0.5234 1" mesh="right_thumb1" />
                                                <geom size="0.01 0.0103942" pos="-0.00662821 0.0003009 0.008001" quat="0.940679 -0.0153872 -0.338948 0" type="capsule" rgba="0.917969 0.765 0.5234 1" />
                                                <body name="right_thumb2" pos="-0.0196332 0.000891287 0.0236996">
                                                    <inertial pos="-0.0107558 -0.00234512 0.00848123" quat="0.0751459 0.74947 0.234612 0.614496" mass="0.00817518" diaginertia="6.78363e-07 6.3602e-07 4.31521e-07" />
                                                    <joint name="right_thumb2_x" pos="0 0 0" axis="1 0 0" limited="true" range="-1.56 1.8" dclass="pip" frictionloss="0.0001" />
                                                    <body name="right_thumb2_y" pos="0 0 0">
                                                        <inertial pos="0 0 0" mass="0.01" diaginertia="0.01 0.01 0.01" />
                                                        <joint name="right_thumb2_y" pos="0 0 0" axis="0 1 0" limited="true" range="-1.52 1.8" dclass="pip" frictionloss="0.0001" />
                                                        <body name="right_thumb2_z" pos="0 0 0">
                                                            <inertial pos="0 0 0" mass="0.01" diaginertia="0.01 0.01 0.01" />
                                                            <joint name="right_thumb2_z" pos="0 0 0" axis="0 0 1" limited="true" range="-1.52 2.5" dclass="pip" frictionloss="0.0001" />
                                                            <geom pos="-0.051947 0.00824762 -0.0556987" type="mesh" contype="0" conaffinity="0" group="1" rgba="0.917969 0.765 0.5234 1" mesh="right_thumb2" />
                                                            <geom size="0.01 0.00854709" pos="-0.00700878 -0.00171388 0.00458176" quat="0.876373 0.114404 -0.467848 0" type="capsule" rgba="0.917969 0.765 0.5234 1" />
                                                            <body name="right_thumb3" pos="-0.0222177 -0.00543297 0.0145241">
                                                                <inertial pos="-0.0117975 -0.00227036 0.00918961" quat="0.0629763 0.836011 0.308321 0.449509" mass="0.00747772" diaginertia="6.95918e-07 6.64502e-07 3.13578e-07" />
                                                                <joint name="right_thumb3_x" pos="0 0 0" axis="1 0 0" limited="true" range="-1.32 1.85" dclass="dip" frictionloss="0.0001" />
                                                                <body name="right_thumb3_y" pos="0 0 0">
                                                                    <inertial pos="0 0 0" mass="0.01" diaginertia="0.01 0.01 0.01" />
                                                                    <joint name="right_thumb3_y" pos="0 0 0" axis="0 1 0" limited="true" range="-1.03 1.2" dclass="dip" frictionloss="0.0001" />
                                                                    <body name="right_thumb3_z" pos="0 0 0">
                                                                        <inertial pos="-0.0130068 -0.00133922 0.0119411" quat="0.259779 0.636128 0.657659 0.308774" mass="0.02" diaginertia="0.0200063 0.0200063 0.02" />
                                                                        <joint name="right_thumb3_z" pos="0 0 0" axis="0 0 1" limited="true" range="-0.86 1.36" dclass="dip" frictionloss="0.0001" />
                                                                        <geom pos="-0.0297292 0.0136806 -0.0702228" type="mesh" contype="0" conaffinity="0" group="1" rgba="0.917969 0.765 0.5234 1" mesh="right_thumb3" />
                                                                        <geom size="0.01 0.0139902" pos="-0.0114239 -0.00246002 0.007692" quat="0.880288 0.0998761 -0.463808 0" type="capsule" rgba="0.917969 0.765 0.5234 1" />
                                                                    </body>
                                                                </body>
                                                            </body>
                                                        </body>
                                                    </body>
                                                </body>
                                            </body>
                                        </body>
                                    </body>
                                </body>
                            </body>
                        </body>
                    </body>
                </body>
            </body>
        </body>
    </worldbody>
    
    <actuator>
        <!-- 腕部关节组（wrist） -->
        <motor name="right_wrist_x" joint="right_wrist_x" dclass="wrist"/>
        <motor name="right_wrist_y" joint="right_wrist_y" dclass="wrist"/>
        <motor name="right_wrist_z" joint="right_wrist_z" dclass="wrist"/>
        <motor name="right_wrist_rx" joint="right_wrist_rx" dclass="wrist"/>
        <motor name="right_wrist_ry" joint="right_wrist_ry" dclass="wrist"/>
        <motor name="right_wrist" joint="right_wrist" dclass="wrist"/>
        <!-- 食指 -->
        <motor name="right_index1_x" joint="right_index1_x" dclass="mcp"/>
        <motor name="right_index1_y" joint="right_index1_y" dclass="mcp"/>
        <motor name="right_index1_z" joint="right_index1_z" dclass="mcp"/>
        <motor name="right_index2_x" joint="right_index2_x" dclass="pip"/>
        <motor name="right_index2_y" joint="right_index2_y" dclass="pip"/>
        <motor name="right_index2_z" joint="right_index2_z" dclass="pip"/>
        <motor name="right_index3_x" joint="right_index3_x" dclass="dip"/>
        <motor name="right_index3_y" joint="right_index3_y" dclass="dip"/>
        <motor name="right_index3_z" joint="right_index3_z" dclass="dip"/>
        <!-- 中指（middle） -->
        <motor name="right_middle1_x" joint="right_middle1_x" dclass="mcp"/>
        <motor name="right_middle1_y" joint="right_middle1_y" dclass="mcp"/>
        <motor name="right_middle1_z" joint="right_middle1_z" dclass="mcp"/>
        <motor name="right_middle2_x" joint="right_middle2_x" dclass="pip"/>
        <motor name="right_middle2_y" joint="right_middle2_y" dclass="pip"/>
        <motor name="right_middle2_z" joint="right_middle2_z" dclass="pip"/>
        <motor name="right_middle3_x" joint="right_middle3_x" dclass="dip"/>
        <motor name="right_middle3_y" joint="right_middle3_y" dclass="dip"/>
        <motor name="right_middle3_z" joint="right_middle3_z" dclass="dip"/>
        <!-- 小指（pinky） -->
        <motor name="right_pinky1_x" joint="right_pinky1_x" dclass="mcp"/>
        <motor name="right_pinky1_y" joint="right_pinky1_y" dclass="mcp"/>
        <motor name="right_pinky1_z" joint="right_pinky1_z" dclass="mcp"/>
        <motor name="right_pinky2_x" joint="right_pinky2_x" dclass="pip"/>
        <motor name="right_pinky2_y" joint="right_pinky2_y" dclass="pip"/>
        <motor name="right_pinky2_z" joint="right_pinky2_z" dclass="pip"/>
        <motor name="right_pinky3_x" joint="right_pinky3_x" dclass="dip"/>
        <motor name="right_pinky3_y" joint="right_pinky3_y" dclass="dip"/>
        <motor name="right_pinky3_z" joint="right_pinky3_z" dclass="dip"/>
        <!-- 无名指（ring） -->
        <motor name="right_ring1_x" joint="right_ring1_x" dclass="mcp"/>
        <motor name="right_ring1_y" joint="right_ring1_y" dclass="mcp"/>
        <motor name="right_ring1_z" joint="right_ring1_z" dclass="mcp"/>
        <motor name="right_ring2_x" joint="right_ring2_x" dclass="pip"/>
        <motor name="right_ring2_y" joint="right_ring2_y" dclass="pip"/>
        <motor name="right_ring2_z" joint="right_ring2_z" dclass="pip"/>
        <motor name="right_ring3_x" joint="right_ring3_x" dclass="dip"/>
        <motor name="right_ring3_y" joint="right_ring3_y" dclass="dip"/>
        <motor name="right_ring3_z" joint="right_ring3_z" dclass="dip"/>
        <!-- 拇指（thumb）特殊处理 -->
        <motor name="right_thumb1_x" joint="right_thumb1_x" dclass="mcp"/> <!-- 掌指关节 -->
        <motor name="right_thumb1_y" joint="right_thumb1_y" dclass="mcp"/>
        <motor name="right_thumb1_z" joint="right_thumb1_z" dclass="mcp"/>
        <motor name="right_thumb2_x" joint="right_thumb2_x" dclass="pip"/> <!-- 指间关节 -->
        <motor name="right_thumb2_y" joint="right_thumb2_y" dclass="pip"/>
        <motor name="right_thumb2_z" joint="right_thumb2_z" dclass="pip"/>
        <motor name="right_thumb3_x" joint="right_thumb3_x" dclass="dip"/> <!-- 末端关节 -->
        <motor name="right_thumb3_y" joint="right_thumb3_y" dclass="dip"/>
        <motor name="right_thumb3_z" joint="right_thumb3_z" dclass="dip"/>
    </actuator>
</mujoco>
